<?xml version="1.0" encoding="UTF-8"?>
<!-- Generated by org.testng.reporters.JUnitReportReporter -->
<testsuite skipped="0" hostname="172_17_0_13" name="com.webtest.renzixuan.Xiangqing" tests="7" failures="1" timestamp="17 十二月 2019 13:26:33 GMT" time="133.360" errors="0">
  <testcase name="test7" time="19.344" classname="com.webtest.renzixuan.Xiangqing"/>
  <testcase name="test4" time="22.562" classname="com.webtest.renzixuan.Xiangqing"/>
  <testcase name="test3" time="22.688" classname="com.webtest.renzixuan.Xiangqing"/>
  <testcase name="test6" time="16.063" classname="com.webtest.renzixuan.Xiangqing"/>
  <testcase name="test5" time="13.000" classname="com.webtest.renzixuan.Xiangqing">
    <failure type="java.lang.AssertionError" message="expected [false] but found [true]">
      <![CDATA[java.lang.AssertionError: expected [false] but found [true]
at org.testng.Assert.fail(Assert.java:96)
at org.testng.Assert.failNotEquals(Assert.java:776)
at org.testng.Assert.assertFalse(Assert.java:65)
at org.testng.Assert.assertFalse(Assert.java:75)
at com.webtest.renzixuan.Xiangqing.test5(Unknown Source)
at sun.reflect.NativeMethodAccessorImpl.invoke0(Native Method)
at sun.reflect.NativeMethodAccessorImpl.invoke(NativeMethodAccessorImpl.java:62)
at sun.reflect.DelegatingMethodAccessorImpl.invoke(DelegatingMethodAccessorImpl.java:43)
at java.lang.reflect.Method.invoke(Method.java:497)
at org.testng.internal.MethodInvocationHelper.invokeMethod(MethodInvocationHelper.java:124)
at org.testng.internal.Invoker.invokeMethod(Invoker.java:580)
at org.testng.internal.Invoker.invokeTestMethod(Invoker.java:716)
at org.testng.internal.Invoker.invokeTestMethods(Invoker.java:988)
at org.testng.internal.TestMethodWorker.invokeTestMethods(TestMethodWorker.java:125)
at org.testng.internal.TestMethodWorker.run(TestMethodWorker.java:109)
at org.testng.TestRunner.privateRun(TestRunner.java:648)
at org.testng.TestRunner.run(TestRunner.java:505)
at org.testng.SuiteRunner.runTest(SuiteRunner.java:455)
at org.testng.SuiteRunner.runSequentially(SuiteRunner.java:450)
at org.testng.SuiteRunner.privateRun(SuiteRunner.java:415)
at org.testng.SuiteRunner.run(SuiteRunner.java:364)
at org.testng.SuiteRunnerWorker.runSuite(SuiteRunnerWorker.java:52)
at org.testng.SuiteRunnerWorker.run(SuiteRunnerWorker.java:84)
at org.testng.TestNG.runSuitesSequentially(TestNG.java:1208)
at org.testng.TestNG.runSuitesLocally(TestNG.java:1137)
at org.testng.TestNG.runSuites(TestNG.java:1049)
at org.testng.TestNG.run(TestNG.java:1017)
at org.testng.TestNG.privateMain(TestNG.java:1354)
at org.testng.TestNG.main(TestNG.java:1323)
]]>
    </failure>
  </testcase> <!-- test5 -->
  <testcase name="test2" time="15.562" classname="com.webtest.renzixuan.Xiangqing"/>
  <testcase name="test1" time="24.141" classname="com.webtest.renzixuan.Xiangqing"/>
</testsuite> <!-- com.webtest.renzixuan.Xiangqing -->
